<?xml version="1.0"?>
<robot name="example">
  <link name="link1">
    <inertial>
      <mass value="1"/>
      <inertia ixx="1" iyy="1" izz="1" ixy="0" ixz="0" iyz="0"/>
    </inertial>
  </link>
  <link name="link2">
    <inertial>
      <mass value="1"/>
      <inertia ixx="1" iyy="1" izz="1" ixy="0" ixz="0" iyz="0"/>
    </inertial>
  </link>
  <joint name="test_joint" type="revolute">
    <parent link="link1"/>
    <child link="link2"/>
    <limit lower="-10000.0" upper="10000.0" effort="3.0" velocity="10.0">
    ## effort in  (N-m )
    ## velocity in rad/s
    </limit>
  </joint>
  <transmission name="test_joint_trans">
    <type>transmission_interface/SimpleTransmission</type>
    <joint name="test_joint">
      <!-- <hardwareInterface>hardware_interface/VelocityJointInterface</hardwareInterface> -->
      <hardwareInterface>hardware_interface/PositionJointInterface</hardwareInterface>
    </joint>
    <actuator name="test_joint_actuator">
      <mechanicalReduction>330.625</mechanicalReduction> <!-- 529/16 -->
      <!-- <mechanicalReduction>333.0</mechanicalReduction> -->
    </actuator>
  </transmission>

  <link name="link3">
    <inertial>
      <mass value="1"/>
      <inertia ixx="1" iyy="1" izz="1" ixy="0" ixz="0" iyz="0"/>
    </inertial>
  </link>
  <link name="link4">
    <inertial>
      <mass value="1"/>
      <inertia ixx="1" iyy="1" izz="1" ixy="0" ixz="0" iyz="0"/>
    </inertial>
  </link>
  <joint name="test_joint3" type="revolute">
    <parent link="link3"/>
    <child link="link4"/>
    <limit lower="-10000.0" upper="10000.0" effort="3.0" velocity="10.0">
    ## effort in  (N-m )
    ## velocity in rad/s
    </limit>
  </joint>
  <transmission name="test_joint_trans3">
    <type>transmission_interface/SimpleTransmission</type>
    <joint name="test_joint3">
      <!-- <hardwareInterface>hardware_interface/VelocityJointInterface</hardwareInterface> -->
      <hardwareInterface>hardware_interface/PositionJointInterface</hardwareInterface>
    </joint>
    <actuator name="test_joint_actuator3">
      <mechanicalReduction>330.625</mechanicalReduction> <!-- 529/16 -->
      <!-- <mechanicalReduction>333.0</mechanicalReduction> -->
    </actuator>
  </transmission>







</robot>
